#!/usr/bin/env python3
# -*- coding:utf-8 -*-
'文档测试'
'''
Python内置的“文档测试”（doctest）模块可以直接提取注释中的代码并执行测试。

doctest严格按照Python交互式命令行的输入和输出来判断测试结果是否正确。只有测试异常的时候，可以用...表示中间一大段烦人的输出。

小结
    doctest非常有用，不但可以用来测试，还可以直接作为示例代码。通过某些文档生成工具，就可以自动把包含doctest的注释提取出来。用户看文档的时候，同时也看到了doctest。

让我们用doctest来测试上次编写的Dict类：
'''
class Dict(dict):
    '''
    Simple dict but also support access as x.y style.

    >>> d1 = Dict()
    >>> d1['x'] = 100
    >>> d1.x
    100
    >>> d1.y = 200
    >>> d1['y']
    200
    >>> d2 = Dict(a=1, b=2, c='3')
    >>> d2.c
    '3'
    >>> d2['empty']
    Traceback (most recent call last):
        ...
    KeyError: 'empty'
    >>> d2.empty
    Traceback (most recent call last):
        ...
    AttributeError: 'Dict' object has no attribute 'empty'
    '''
    def __init__(self, **kw):
        super(Dict, self).__init__(**kw)

    def __getattr__(self, key):
        try:
            return self[key]
        except KeyError:
            raise AttributeError(r"'Dict' object has no attribute '%s'" % key)

    def __setattr__(self, key, value):
        self[key] = value

if __name__=='__main__':
    import doctest
    doctest.testmod()
'''
运行python mydict2.py： $ python mydict2.py
什么输出也没有。这说明我们编写的doctest运行都是正确的。如果程序有问题，比如把__getattr__()方法注释掉，再运行就会报错：
$ python mydict2.py
**********************************************************************
File "/Users/michael/Github/learn-python3/samples/debug/mydict2.py", line 10, in __main__.Dict
Failed example:
    d1.x
Exception raised:
    Traceback (most recent call last):
      ...
    AttributeError: 'Dict' object has no attribute 'x'
**********************************************************************
File "/Users/michael/Github/learn-python3/samples/debug/mydict2.py", line 16, in __main__.Dict
Failed example:
    d2.c
Exception raised:
    Traceback (most recent call last):
      ...
    AttributeError: 'Dict' object has no attribute 'c'
**********************************************************************
1 items had failures:
   2 of   9 in __main__.Dict
***Test Failed*** 2 failures.

注意到最后3行代码。当模块正常导入时，doctest不会被执行。只有在命令行直接运行时，才执行doctest。所以，不必担心doctest会在非测试环境下执行。
'''

def fact(n):
    '''
    Calculate 1*2*3...*n
    >>> fact(1)
    1
    >>> fact(10)

    >>> fact(-1)
    
    '''
    if n<1:
        raise ValueError()
    if n==1:
        return 1
    return n*fact(n-1)

print("fact(10) =", fact(10))

if __name__ == '__main__':
    import doctest
    doctest.testmod()